Workbook

Sheet ACORDS
I1: PC03.F01 Acta d'avaluació Ed.02 - Setem.25
B2: #VALUE! | D2: #VALUE!
I3: GRUP | J3: =IF(ficha_alum!K3 = "", "", ficha_alum!K3)
I4: TUTOR/A | J4: =IF(ficha_alum!K4 = "", "", ficha_alum!K4)
I5: CURS ESCOLAR | J5: =IF(ficha_alum!K5 = "", "", ficha_alum!K5)
B7: Resum acords adoptats de caràcter col·legiat
B9: Avaluació inicial | D9: 1
D10: 2
D11: 3
D12: 4
D13: 5
D14: 6
D15: 7
B17: Primera parcial | D17: 1
D18: 2
D19: 3
D20: 4
D21: 5
D22: 6
D23: 7
B25: Segona parcial | D25: 1
D26: 2
D27: 3
D28: 4
D29: 5
D30: 6
D31: 7
B33: Avaluació final ordinaria | D33: 1
D34: 2
D35: 3
D36: 4
D37: 5
D38: 6
D39: 7
B41: Avaluació extraordinària | D41: 1
D42: 2
D43: 3
D44: 4
D45: 5
D46: 6
...

Sheet 0 AVAL
H1: PC03.F01 Acta d'avaluació Ed.02 - Setem.25
B2: #VALUE! | D2: #VALUE!
H3: GRUP | J3: =IF(ficha_alum!K3 = "", "", ficha_alum!K3)
H4: TUTOR/A | J4: =IF(ficha_alum!K4 = "", "", ficha_alum!K4)
H5: CURS ESCOLAR | J5: =IF(ficha_alum!K5 = "", "", ficha_alum!K5)
H6: AVALUACIÓ | J6: Avaluació 0 (inicial)
H7: DATA SESSIÓ | J7: 45901
B9: 1- Informe sobre els aspectes generals del grup
B11: Valoració de l'assistència i puntualitat a classe. Gestió del temps i compromís amb l'aprenentatge.
B14: Valoració de les competències actitudinals i hàbits de treball.
B17: Valoració de l'ambient de la classe, interacció entre l'alumnat: convivència, participació i col·laboració.
B20: 2- Informació traslladada per l'alumnat
B21: Identificació de mòduls i resultats d'aprenentatge amb majors dificultats. Falta de desenvolupament de determinades competències.
B24: 3- Estadístiques sobre el context del grup
B26: Via d'accés de l'alumnat | G26: Experiència professional prèvia | M26: Total alumnat grup | O26: =COUNTIFS($C$36:$C$75,"<>",$D$36:$D$75,"<>Baixa") -> 40 | P26: % sobre total
B27: Núm. alumnat ESO | D27: 0 | E27: =IFERROR(D27/$O$26,"-") -> 0 | F27: Núm. alumnat experiència relacionada amb el cicle | J27: 0 | K27: =IFERROR(J27/$O$26,"-") -> 0 | M27: Núm. baixes confirmades | O27: =COUNTIFS($D$36:$D$75,"Baixa") -> 0 | P27: =IFERROR(O27/$O$26,"-") -> 0
B28: Núm. alumnat batxillerat | D28: 0 | E28: =IFERROR(D28/$O$26,"-") -> 0 | F28: Núm. alumnat experiència una altra família professional | J28: 0 | K28: =IFERROR(J28/$O$26,"-") -> 0 | M28: Total alumnat absentista | O28: 0 | P28: =IFERROR(O28/$O$26,"-") -> 0
B29: Núm. alumnat Proves d'accés | D29: 0 | E29: =IFERROR(D29/$O$26,"-") -> 0 | F29: Núm. alumnat sense experiència professional | J29: 0 | K29: =IFERROR(J29/$O$26,"-") -> 0 | M29: Total alumnat NESE | O29: =COUNTIFS($C$36:$C$75,"<>",$D$36:$D$75,"<>Baixa",$K$36:$K$75,"Sí") -> 0 | P29: =IFERROR(O29/$O$26,"-") -> 0
B30: Núm. alumnat altres titulacions | D30: 0 | E30: =IFERROR(D30/$O$26,"-") -> 0 | J30: No coincideix amb el total del grup | M30: Total alumnat amb pendents | O30: =COUNTIFS($C$36:$C$75,"<>",$D$36:$D$75,"<>Baixa",$I$36:$I$75,"Sí") -> 0 | P30: =IFERROR(O30/$O$26,"-") -> 0
D31: No coincideix amb el total del grup | M31: Total alumnat repetidor | O31: =COUNTIFS($C$36:$C$75,"<>",$D$36:$D$75,"<>Baixa",$J$36:$J$75,"Sí") -> 0 | P31: =IFERROR(O31/$O$26,"-") -> 0
B33: 4- Anàlisi individual de l'alumnat
B35: NIA | C35: Alumne/a | D35: Estat 1rT | E35: NUSS | F35: Certif. digital | G35: Autorització imatges | H35: Alerta sanitària | I35: Pendents | J35: Repetidor/a | K35: NESE | L35: Situació familiar | M35: Observacions - Seguiment individual - Mesures d'inclusió - Pla recuperació Convalidacions - Exempcions
A36: 1 | B36: =IF(ficha_alum!B9="","",ficha_alum!B9) | C36: =_xlfn.TEXTJOIN(", ",TRUE,_xlfn.TEXTJOIN(" ",TRUE,ficha_alum!D9,ficha_alum!E9),ficha_alum!C9) | D36: Alta | E36: =IF(ficha_alum!F9="","",ficha_alum!F9) | F36: No | G36: No | H36: No | I36: No | J36: No | K36: No
A37: 2 | B37: =IF(ficha_alum!B10="","",ficha_alum!B10) | C37: =_xlfn.TEXTJOIN(", ",TRUE,_xlfn.TEXTJOIN(" ",TRUE,ficha_alum!D10,ficha_alum!E10),ficha_alum!C10) | D37: Alta | E37: =IF(ficha_alum!F10="","",ficha_alum!F10) | F37: No | G37: No | H37: No | I37: No | J37: No | K37: No
A38: 3 | B38: =IF(ficha_alum!B11="","",ficha_alum!B11) | C38: =_xlfn.TEXTJOIN(", ",TRUE,_xlfn.TEXTJOIN(" ",TRUE,ficha_alum!D11,ficha_alum!E11),ficha_alum!C11) | D38: Alta | E38: =IF(ficha_alum!F11="","",ficha_alum!F11) | F38: No | G38: No | H38: No | I38: No | J38: No | K38: No
A39: 4 | B39: =IF(ficha_alum!B12="","",ficha_alum!B12) | C39: =_xlfn.TEXTJOIN(", ",TRUE,_xlfn.TEXTJOIN(" ",TRUE,ficha_alum!D12,ficha_alum!E12),ficha_alum!C12) | D39: Alta | E39: =IF(ficha_alum!F12="","",ficha_alum!F12) | F39: No | G39: No | H39: No | I39: No | J39: No | K39: No
A40: 5 | B40: =IF(ficha_alum!B13="","",ficha_alum!B13) | C40: =_xlfn.TEXTJOIN(", ",TRUE,_xlfn.TEXTJOIN(" ",TRUE,ficha_alum!D13,ficha_alum!E13),ficha_alum!C13) | D40: Alta | E40: =IF(ficha_alum!F13="","",ficha_alum!F13) | F40: No | G40: No | H40: No | I40: No | J40: No | K40: No
A41: 6 | B41: =IF(ficha_alum!B14="","",ficha_alum!B14) | C41: =_xlfn.TEXTJOIN(", ",TRUE,_xlfn.TEXTJOIN(" ",TRUE,ficha_alum!D14,ficha_alum!E14),ficha_alum!C14) | D41: Alta | E41: =IF(ficha_alum!F14="","",ficha_alum!F14) | F41: No | G41: No | H41: No | I41: No | J41: No | K41: No
A42: 7 | B42: =IF(ficha_alum!B15="","",ficha_alum!B15) | C42: =_xlfn.TEXTJOIN(", ",TRUE,_xlfn.TEXTJOIN(" ",TRUE,ficha_alum!D15,ficha_alum!E15),ficha_alum!C15) | D42: Alta | E42: =IF(ficha_alum!F15="","",ficha_alum!F15) | F42: No | G42: No | H42: No | I42: No | J42: No | K42: No
A43: 8 | B43: =IF(ficha_alum!B16="","",ficha_alum!B16) | C43: =_xlfn.TEXTJOIN(", ",TRUE,_xlfn.TEXTJOIN(" ",TRUE,ficha_alum!D16,ficha_alum!E16),ficha_alum!C16) | D43: Alta | E43: =IF(ficha_alum!F16="","",ficha_alum!F16) | F43: No | G43: No | H43: No | I43: No | J43: No | K43: No
A44: 9 | B44: =IF(ficha_alum!B17="","",ficha_alum!B17) | C44: =_xlfn.TEXTJOIN(", ",TRUE,_xlfn.TEXTJOIN(" ",TRUE,ficha_alum!D17,ficha_alum!E17),ficha_alum!C17) | D44: Alta | E44: =IF(ficha_alum!F17="","",ficha_alum!F17) | F44: No | G44: No | H44: No | I44: No | J44: No | K44: No
A45: 10 | B45: =IF(ficha_alum!B18="","",ficha_alum!B18) | C45: =_xlfn.TEXTJOIN(", ",TRUE,_xlfn.TEXTJOIN(" ",TRUE,ficha_alum!D18,ficha_alum!E18),ficha_alum!C18) | D45: Alta | E45: =IF(ficha_alum!F18="","",ficha_alum!F18) | F45: No | G45: No | H45: No | I45: No | J45: No | K45: No
A46: 11 | B46: =IF(ficha_alum!B19="","",ficha_alum!B19) | C46: =_xlfn.TEXTJOIN(", ",TRUE,_xlfn.TEXTJOIN(" ",TRUE,ficha_alum!D19,ficha_alum!E19),ficha_alum!C19) | D46: Alta | E46: =IF(ficha_alum!F19="","",ficha_alum!F19) | F46: No | G46: No | H46: No | I46: No | J46: No | K46: No
A47: 12 | B47: =IF(ficha_alum!B20="","",ficha_alum!B20) | C47: =_xlfn.TEXTJOIN(", ",TRUE,_xlfn.TEXTJOIN(" ",TRUE,ficha_alum!D20,ficha_alum!E20),ficha_alum!C20) | D47: Alta | E47: =IF(ficha_alum!F20="","",ficha_alum!F20) | F47: No | G47: No | H47: No | I47: No | J47: No | K47: No
... A75: 40 | B75: =IF(ficha_alum!B48="","",ficha_alum!B48) | C75: =_xlfn.TEXTJOIN(", ",TRUE,_xlfn.TEXTJOIN(" ",TRUE,ficha_alum!D48,ficha_alum!E48),ficha_alum!C48) | D75: Alta | E75: =IF(ficha_alum!F48="","",ficha_alum!F48) | F75: No | G75: No | H75: No | I75: No | J75: No | K75: No
B77: 5- Acords adoptats de caràcter col·legiat per l'equip docent
A79: 1 | B79: =IF(ACORDS!E9 = "", "", ACORDS!E9) | L79: Acta elaborada per: XXXXX. XX:XXh
A80: 2 | B80: =IF(ACORDS!E10 = "", "", ACORDS!E10)
A81: 3 | B81: =IF(ACORDS!E11 = "", "", ACORDS!E11)
A82: 4 | B82: =IF(ACORDS!E12 = "", "", ACORDS!E12)
...

Sheet 1a PARCIAL
I1: PC03.F01 Acta d'avaluació Ed.02 - Setem.25
B2: #VALUE! | D2: #VALUE!
I3: GRUP | J3: =IF(ficha_alum!K3 = "", "", ficha_alum!K3)
I4: TUTOR/A | J4: =IF(ficha_alum!K4 = "", "", ficha_alum!K4)
I5: CURS ESCOLAR | J5: =IF(ficha_alum!K5 = "", "", ficha_alum!K5)
I6: AVALUACIÓ | J6: Primera parcial
I7: DATA SESSIÓ
B9: 1- Informe sobre els aspectes generals del grup
B11: Valoració de l'assistència i puntualitat a classe. Gestió del temps i compromís amb l'aprenentatge.
B14: Valoració de les competències actitudinals i hàbits de treball.
B17: Valoració de l'ambient de la classe, interacció entre l'alumnat: convivència, participació i la col·laboració.
B20: 2- Informació traslladada per l'alumnat
B21: Identificació de mòduls i resultats d'aprenentatge amb majors dificultats. Falta de desenvolupament de determinades competències.
B24: 3- Estadístiques
B25: Inclou el valor (número) en les cel·les ombrejades en roig
B26: Núm. alumnat total grup | D26: =COUNTIFS($C$36:$C$75,"<>",$D$36:$D$75,"<>Baixa")-COUNTBLANK($C$36:$C$75) -> 0 | E26: % sobre total | G26: Observacions:
B27: Núm. baixes confirmades | D27: =COUNTIFS($D$36:$D$75,"Baixa") -> 0 | E27: =IFERROR(D27/$D$26,"-") -> -
B28: Núm. abandonaments | D28: 0 | E28: =IFERROR(D28/$D$26,"-") -> -
B29: Núm. alumnat NESE | D29: 0 | E29: =IFERROR(D29/$D$26,"-") -> -
B30: Núm. alumnat avaluat | D30: 0 | E30: =IFERROR(D30/$D$26,"-") -> -
B31: Núm. alumnat no avaluat | D31: 0 | E31: =IFERROR(D31/$D$26,"-") -> -
B33: 4- Anàlisi individual de l'alumnat
B35: NIA | C35: Alumne/a | D35: Estat 1rT | E35: Observacions individuals - Mesures d'atenció a la diversitat - Eficàcia de les mesures - Avaluar el progrés de l'alumnat en la consecució dels RA i les competències professionals i per a l'ocupabilitat - Plans de recuperació - Pèrdua de l'avaluació contínua
A36: 1 | B36: =IF('0 AVAL'!B36 = "", "", '0 AVAL'!B36) | C36: =IF('0 AVAL'!C36 = "", "", '0 AVAL'!C36) | D36: Alta
A37: 2 | B37: =IF('0 AVAL'!B37 = "", "", '0 AVAL'!B37) | C37: =IF('0 AVAL'!C37 = "", "", '0 AVAL'!C37) | D37: Alta
A38: 3 | B38: =IF('0 AVAL'!B38 = "", "", '0 AVAL'!B38) | C38: =IF('0 AVAL'!C38 = "", "", '0 AVAL'!C38) | D38: Alta
A39: 4 | B39: =IF('0 AVAL'!B39 = "", "", '0 AVAL'!B39) | C39: =IF('0 AVAL'!C39 = "", "", '0 AVAL'!C39) | D39: Alta
A40: 5 | B40: =IF('0 AVAL'!B40 = "", "", '0 AVAL'!B40) | C40: =IF('0 AVAL'!C40 = "", "", '0 AVAL'!C40) | D40: Alta
A41: 6 | B41: =IF('0 AVAL'!B41 = "", "", '0 AVAL'!B41) | C41: =IF('0 AVAL'!C41 = "", "", '0 AVAL'!C41) | D41: Alta
A42: 7 | B42: =IF('0 AVAL'!B42 = "", "", '0 AVAL'!B42) | C42: =IF('0 AVAL'!C42 = "", "", '0 AVAL'!C42) | D42: Alta
A43: 8 | B43: =IF('0 AVAL'!B43 = "", "", '0 AVAL'!B43) | C43: =IF('0 AVAL'!C43 = "", "", '0 AVAL'!C43) | D43: Alta
A44: 9 | B44: =IF('0 AVAL'!B44 = "", "", '0 AVAL'!B44) | C44: =IF('0 AVAL'!C44 = "", "", '0 AVAL'!C44) | D44: Alta
A45: 10 | B45: =IF('0 AVAL'!B45 = "", "", '0 AVAL'!B45) | C45: =IF('0 AVAL'!C45 = "", "", '0 AVAL'!C45) | D45: Alta
A46: 11 | B46: =IF('0 AVAL'!B46 = "", "", '0 AVAL'!B46) | C46: =IF('0 AVAL'!C46 = "", "", '0 AVAL'!C46) | D46: Alta
A47: 12 | B47: =IF('0 AVAL'!B47 = "", "", '0 AVAL'!B47) | C47: =IF('0 AVAL'!C47 = "", "", '0 AVAL'!C47) | D47: Alta
... A75: 40 | B75: =IF('0 AVAL'!B75 = "", "", '0 AVAL'!B75) | C75: =IF('0 AVAL'!C75 = "", "", '0 AVAL'!C75) | D75: Alta
B77: 5- Seguiments d'acords i mesures adoptades de manera consensuada per l'equip docent en anteriors reunions
J78: Seguiment | K78: Observacions
A79: 1
A80: 2
...

Sheet 2a PARCIAL
I1: PC03.F01 Acta d'avaluació Ed.02 - Setem.25
B2: #VALUE! | D2: #VALUE!
I3: GRUP | J3: =IF(ficha_alum!K3 = "", "", ficha_alum!K3)
I4: TUTOR/A | J4: =IF(ficha_alum!K4 = "", "", ficha_alum!K4)
I5: CURS ESCOLAR | J5: =IF(ficha_alum!K5 = "", "", ficha_alum!K5)
I6: AVALUACIÓ | J6: Segona parcial
I7: DATA SESSIÓ
B9: 1- Informe sobre els aspectes generals del grup
B11: Valoració de l'assistència i puntualitat a classe. Gestió del temps i compromís amb l'aprenentatge.
B14: Valoració de les competències actitudinals i hàbits de treball.
B17: Valoració de l'ambient de la classe, interacció entre l'alumnat: convivència, participació i la col·laboració.
B20: 2- Informació traslladada per l'alumnat
B21: Identificació de mòduls i resultats d'aprenentatge amb majors dificultats. Falta de desenvolupament de determinades competències.
B24: 3- Estadístiques
B25: Inclou el valor (número) en les cel·les ombrejades en roig
B26: Núm. alumnat total grup | D26: =COUNTIFS($C$39:$C$78,"<>",$D$39:$D$78,"<>Baixa")-COUNTBLANK($C$39:$C$78) -> 0 | E26: % sobre total | G26: Previsió alumnat amb condicions de no promocionar | L26: Núm. alu | M26: %
B27: Núm. baixes confirmades | D27: =COUNTIFS($D$39:$D$78,"Baixa") -> 0 | E27: =IFERROR(D27/$D$26,"-") -> - | G27: Bàsica | L27: 0 | M27: =IFERROR(L27/$D$26,"-") -> -
B28: Núm. abandonaments | D28: 0 | E28: =IFERROR(D28/$D$26,"-") -> - | G28: Els mòduls professionals pendents associats a estàndards de competència superen el 20% de l'horari setmanal i no s'ha superat almenys un dels àmbits distints del professional.
B29: Núm. alumnat NESE | D29: 0 | E29: =IFERROR(D29/$D$26,"-") -> - | L29: Núm. alu | M29: %
B30: Núm. alumnat avaluat | D30: 0 | E30: =IFERROR(D30/$D$26,"-") -> - | G30: Mitjà i superior | L30: 0 | M30: =IFERROR(L30/$D$26,"-") -> -
B31: Núm. alumnat no avaluat | D31: 0 | E31: =IFERROR(D31/$D$26,"-") -> - | G31: No haver superat almenys el 80% del total de les hores lectives del primer curs - 200 hores
C33: Observacions:
B36: 4- Anàlisi individual de l'alumnat
B38: NIA | C38: Alumne/a | D38: Estat 2nT | E38: Observacions individuals - Mesures d'atenció a la diversitat - Eficàcia de les mesures - Avaluar el progrés de l'alumnat en la consecució dels RA i les competències professionals i per a l'ocupabilitat - Plans de recuperació - Pèrdua de l'avaluació contínua - No supera PRL
A39: 1 | B39: =IF('0 AVAL'!B36 = "", "", '0 AVAL'!B36) | C39: =IF('0 AVAL'!C36 = "", "", '0 AVAL'!C36)
A40: 2 | B40: =IF('0 AVAL'!B37 = "", "", '0 AVAL'!B37) | C40: =IF('0 AVAL'!C37 = "", "", '0 AVAL'!C37)
A41: 3 | B41: =IF('0 AVAL'!B38 = "", "", '0 AVAL'!B38) | C41: =IF('0 AVAL'!C38 = "", "", '0 AVAL'!C38)
A42: 4 | B42: =IF('0 AVAL'!B39 = "", "", '0 AVAL'!B39) | C42: =IF('0 AVAL'!C39 = "", "", '0 AVAL'!C39)
A43: 5 | B43: =IF('0 AVAL'!B40 = "", "", '0 AVAL'!B40) | C43: =IF('0 AVAL'!C40 = "", "", '0 AVAL'!C40)
A44: 6 | B44: =IF('0 AVAL'!B41 = "", "", '0 AVAL'!B41) | C44: =IF('0 AVAL'!C41 = "", "", '0 AVAL'!C41)
A45: 7 | B45: =IF('0 AVAL'!B42 = "", "", '0 AVAL'!B42) | C45: =IF('0 AVAL'!C42 = "", "", '0 AVAL'!C42)
A46: 8 | B46: =IF('0 AVAL'!B43 = "", "", '0 AVAL'!B43) | C46: =IF('0 AVAL'!C43 = "", "", '0 AVAL'!C43)
A47: 9 | B47: =IF('0 AVAL'!B44 = "", "", '0 AVAL'!B44) | C47: =IF('0 AVAL'!C44 = "", "", '0 AVAL'!C44)
A48: 10 | B48: =IF('0 AVAL'!B45 = "", "", '0 AVAL'!B45) | C48: =IF('0 AVAL'!C45 = "", "", '0 AVAL'!C45)
A49: 11 | B49: =IF('0 AVAL'!B46 = "", "", '0 AVAL'!B46) | C49: =IF('0 AVAL'!C46 = "", "", '0 AVAL'!C46)
A50: 12 | B50: =IF('0 AVAL'!B47 = "", "", '0 AVAL'!B47) | C50: =IF('0 AVAL'!C47 = "", "", '0 AVAL'!C47)
... A78: 40 | B78: =IF('0 AVAL'!B75 = "", "", '0 AVAL'!B75) | C78: =IF('0 AVAL'!C75 = "", "", '0 AVAL'!C75)
B80: 5- Seguiments d'acords i mesures adoptades de manera consensuada per l'equip docent en anteriors reunions
J81: Seguiment | K81: Observacions
A82: 1
...

Sheet FE
J1: PC03.F01 Acta d'avaluació Ed.02 - Setem.25
B2: #VALUE! | D2: #VALUE!
J3: GRUP | L3: =IF(ficha_alum!K3 = "", "", ficha_alum!K3)
J4: TUTOR/A | L4: =IF(ficha_alum!K4 = "", "", ficha_alum!K4)
J5: CURS ESCOLAR | L5: =IF(ficha_alum!K5 = "", "", ficha_alum!K5)
J6: REUNIÓ EQUIP DOCENT | L6: Formació Empreses
J7: DATA REUNIÓ
B9: 1- Informació sobre les pràctiques formatives
B11: NIA | C11: Alumne/a | D11: Estat 2nT | E11: Núm. FE | F11: Accés pràctiques | G11: Motius de no accés | H11: Empresa | J11: Cesse | K11: Motiu cesse | L11: Hores FE realitzades | M11: FE superada | N11: Inserció laboral | O11: Observacions
A12: 1 | B12: =IF('0 AVAL'!B36 = "", "", '0 AVAL'!B36) | C12: =IF('0 AVAL'!C36 = "", "", '0 AVAL'!C36) | F12: - | G12: - | J12: - | M12: - | N12: -
A13: 2 | B13: =IF('0 AVAL'!B37 = "", "", '0 AVAL'!B37) | C13: =IF('0 AVAL'!C37 = "", "", '0 AVAL'!C37) | F13: - | G13: - | J13: - | M13: - | N13: -
A14: 3 | B14: =IF('0 AVAL'!B38 = "", "", '0 AVAL'!B38) | C14: =IF('0 AVAL'!C38 = "", "", '0 AVAL'!C38) | F14: - | G14: - | J14: - | M14: - | N14: -
A15: 4 | B15: =IF('0 AVAL'!B39 = "", "", '0 AVAL'!B39) | C15: =IF('0 AVAL'!C39 = "", "", '0 AVAL'!C39) | F15: - | G15: - | J15: - | M15: - | N15: -
A16: 5 | B16: =IF('0 AVAL'!B40 = "", "", '0 AVAL'!B40) | C16: =IF('0 AVAL'!C40 = "", "", '0 AVAL'!C40) | F16: - | G16: - | J16: - | M16: - | N16: -
A17: 6 | B17: =IF('0 AVAL'!B41 = "", "", '0 AVAL'!B41) | C17: =IF('0 AVAL'!C41 = "", "", '0 AVAL'!C41) | F17: - | G17: - | J17: - | M17: - | N17: -
A18: 7 | B18: =IF('0 AVAL'!B42 = "", "", '0 AVAL'!B42) | C18: =IF('0 AVAL'!C42 = "", "", '0 AVAL'!C42) | F18: - | G18: - | J18: - | M18: - | N18: -
A19: 8 | B19: =IF('0 AVAL'!B43 = "", "", '0 AVAL'!B43) | C19: =IF('0 AVAL'!C43 = "", "", '0 AVAL'!C43) | F19: - | G19: - | J19: - | M19: - | N19: -
A20: 9 | B20: =IF('0 AVAL'!B44 = "", "", '0 AVAL'!B44) | C20: =IF('0 AVAL'!C44 = "", "", '0 AVAL'!C44) | F20: - | G20: - | J20: - | M20: - | N20: -
A21: 10 | B21: =IF('0 AVAL'!B45 = "", "", '0 AVAL'!B45) | C21: =IF('0 AVAL'!C45 = "", "", '0 AVAL'!C45) | F21: - | G21: - | J21: - | M21: - | N21: -
A22: 11 | B22: =IF('0 AVAL'!B46 = "", "", '0 AVAL'!B46) | C22: =IF('0 AVAL'!C46 = "", "", '0 AVAL'!C46) | F22: - | G22: - | J22: - | M22: - | N22: -
A23: 12 | B23: =IF('0 AVAL'!B47 = "", "", '0 AVAL'!B47) | C23: =IF('0 AVAL'!C47 = "", "", '0 AVAL'!C47) | F23: - | G23: - | J23: - | M23: - | N23: -
... A51: 40 | B51: =IF('0 AVAL'!B75 = "", "", '0 AVAL'!B75) | C51: =IF('0 AVAL'!C75 = "", "", '0 AVAL'!C75) | F51: - | G51: - | J51: - | M51: - | N51: -
F52: 00,00% Sí | J52: 00,00% Sí | M52: 00,00% Sí | N52: 00,00% Sí
B54: 2- Acords adoptats de caràcter col·legiat per l'equip docent
A56: 1 | K56: Acta elaborada per: XXXXX. XX:XXh
A57: 2
A58: 3
A59: 4
A60: 5
A61: 6
A62: 7
B63: En aquest document s'està realitzant un tractament de dades de l'alumnat que està regulat per la normativa vigent en matèria de Protecció de Dades de Caràcter Personal (LOPD 3/2018 i Resolució Conselleria Educació, Investigació, Cultura i Esport del 28/6/2018). Recorda que les dades han de ser tractats de manera responsable i que has de guardar secret professional i no cedir o divulgar les dades ací contingudes.

Sheet PI
J1: PC03.F01 Acta d'avaluació Ed.02 - Setem.25
B2: #VALUE! | D2: #VALUE!
J3: GRUP | K3: =IF(ficha_alum!K3 = "", "", ficha_alum!K3)
J4: TUTOR/A | K4: =IF(ficha_alum!K4 = "", "", ficha_alum!K4)
K5: =IF(ficha_alum!K5 = "", "", ficha_alum!K5)
J6: CURS ESCOLAR | K6: =IF(ficha_alum!K6 = "", "", ficha_alum!K6)
J7: REUNIÓ EQUIP DOCENT | K7: Projecte Intermodular
J8: DATA REUNIÓ
B10: 1- Informació sobre el Projecte Intermodular
F11: 0.5 | J11: 0.5
B12: NIA | C12: Alumne/a | D12: Estat 3rT | F12: Nota PI 1r curs | G12: Observacions | J12: Nota PI 2n curs | K12: Observacions | N12: Nota PI 2n curs | O12: Observacions
A13: 1 | B13: =IF('0 AVAL'!B36 = "", "", '0 AVAL'!B36) | C13: =IF('0 AVAL'!C36 = "", "", '0 AVAL'!C36) | N13: -
A14: 2 | B14: =IF('0 AVAL'!B37 = "", "", '0 AVAL'!B37) | C14: =IF('0 AVAL'!C37 = "", "", '0 AVAL'!C37) | N14: -
A15: 3 | B15: =IF('0 AVAL'!B38 = "", "", '0 AVAL'!B38) | C15: =IF('0 AVAL'!C38 = "", "", '0 AVAL'!C38) | N15: -
A16: 4 | B16: =IF('0 AVAL'!B39 = "", "", '0 AVAL'!B39) | C16: =IF('0 AVAL'!C39 = "", "", '0 AVAL'!C39) | N16: -
A17: 5 | B17: =IF('0 AVAL'!B40 = "", "", '0 AVAL'!B40) | C17: =IF('0 AVAL'!C40 = "", "", '0 AVAL'!C40) | N17: -
A18: 6 | B18: =IF('0 AVAL'!B41 = "", "", '0 AVAL'!B41) | C18: =IF('0 AVAL'!C41 = "", "", '0 AVAL'!C41) | N18: -
A19: 7 | B19: =IF('0 AVAL'!B42 = "", "", '0 AVAL'!B42) | C19: =IF('0 AVAL'!C42 = "", "", '0 AVAL'!C42) | N19: -
A20: 8 | B20: =IF('0 AVAL'!B43 = "", "", '0 AVAL'!B43) | C20: =IF('0 AVAL'!C43 = "", "", '0 AVAL'!C43) | N20: -
A21: 9 | B21: =IF('0 AVAL'!B44 = "", "", '0 AVAL'!B44) | C21: =IF('0 AVAL'!C44 = "", "", '0 AVAL'!C44) | N21: -
A22: 10 | B22: =IF('0 AVAL'!B45 = "", "", '0 AVAL'!B45) | C22: =IF('0 AVAL'!C45 = "", "", '0 AVAL'!C45) | N22: -
A23: 11 | B23: =IF('0 AVAL'!B46 = "", "", '0 AVAL'!B46) | C23: =IF('0 AVAL'!C46 = "", "", '0 AVAL'!C46) | N23: -
A24: 12 | B24: =IF('0 AVAL'!B47 = "", "", '0 AVAL'!B47) | C24: =IF('0 AVAL'!C47 = "", "", '0 AVAL'!C47) | N24: -
... A52: 40 | B52: =IF('0 AVAL'!B75 = "", "", '0 AVAL'!B75) | C52: =IF('0 AVAL'!C75 = "", "", '0 AVAL'!C75) | N52: -
B54: 2- Acords adoptats de caràcter col·legiat per l'equip docent
A55: 1 | K55: Acta elaborada per: XXXXX. XX:XXh
A56: 2
A57: 3
A58: 4
A59: 5
A60: 6
A61: 7
B62: En aquest document s'està realitzant un tractament de dades de l'alumnat que està regulat per la normativa vigent en matèria de Protecció de Dades de Caràcter Personal (LOPD 3/2018 i Resolució Conselleria Educació, Investigació, Cultura i Esport del 28/6/2018). Recorda que les dades han de ser tractats de manera responsable i que has de guardar secret professional i no cedir o divulgar les dades ací contingudes.

Sheet FINAL
I1: PC03.F01 Acta d'avaluació Ed.02 - Setem.25
B2: #VALUE! | D2: #VALUE!
I3: GRUP | J3: =IF(ficha_alum!K3 = "", "", ficha_alum!K3)
I4: TUTOR/A | J4: =IF(ficha_alum!K4 = "", "", ficha_alum!K4)
I5: CURS ESCOLAR | J5: =IF(ficha_alum!K5 = "", "", ficha_alum!K5)
I6: AVALUACIÓ | J6: Avaluació final
I7: DATA REUNIÓ
B9: 1- Informe sobre els aspectes generals del grup
B11: Valoració de l'assistència i puntualitat a classe. Gestió del temps i compromís amb l'aprenentatge.
N12: -
B14: Valoració de les competències actitudinals i hàbits de treball.
B17: Valoració de l'ambient de la classe, interacció entre l'alumnat: convivència, participació i la col·laboració.
B20: 2- Informació traslladada per l'alumnat
B21: Identificació de mòduls i resultats d'aprenentatge amb majors dificultats. Falta de desenvolupament de determinades competències.
B24: 3- Estadístiques
B25: Inclou el valor (número) en les cel·les ombrejades en roig
D26: Núm. alu | L26: Núm. alu | M26: % sobre total | N26: Sobre avaluats
C27: Núm. alumnat total grup | D27: =COUNTIFS($C$39:$C$78,"<>",$D$39:$D$78,"<>Baixa")-COUNTBLANK($C$39:$C$78) -> 0 | E27: % sobre total | G27: Núm. alumnat amb tot aprovat | L27: 0 | M27: =IFERROR(L27/$D$27,"-") -> - | N27: =IFERROR(L27/$D$31,"-") -> -
C28: Núm. baixes confirmades | D28: =COUNTIFS($D$39:$D$78,"Baixa") -> 0 | E28: =IFERROR(D28/$D$27,"-") -> - | G28: Núm. alumnat amb 1 mòdul suspès | L28: 0 | M28: =IFERROR(L28/$D$27,"-") -> - | N28: =IFERROR(L28/$D$31,"-") -> -
C29: Núm. abandonaments | D29: 0 | E29: =IFERROR(D29/$D$27,"-") -> - | G29: Núm. alumnat amb 2 mòduls suspesos | L29: 0 | M29: =IFERROR(L29/$D$27,"-") -> - | N29: =IFERROR(L29/$D$31,"-") -> -
C30: Núm. alumnat NESE | D30: 0 | E30: =IFERROR(D30/$D$27,"-") -> - | G30: Núm. alumnat amb 3 mòduls suspesos | L30: 0 | M30: =IFERROR(L30/$D$27,"-") -> - | N30: =IFERROR(L30/$D$31,"-") -> -
C31: Núm. alumnat avaluat | D31: 0 | E31: =IFERROR(D31/$D$27,"-") -> - | G31: Núm. alumnat amb 4 o més mòduls suspesos | L31: 0 | M31: =IFERROR(L31/$D$27,"-") -> - | N31: =IFERROR(L31/$D$31,"-") -> -
C32: Núm. alumnat no avaluat | D32: 0 | E32: =IFERROR(D32/$D$27,"-") -> -
G33: Núm. alu. promociona (1r) - titula (2n) | L33: 0 | M33: =IFERROR(L33/$D$27,"-") -> - | N33: =IFERROR(L33/$D$31,"-") -> -
G34: Núm. alu. no promociona (1r) - no titula (2n) | L34: =D27-L33 -> 0 | M34: =IFERROR(L34/$D$27,"-") -> - | N34: =IFERROR(L34/$D$31,"-") -> -
B36: 4- Anàlisi individual de l'alumnat
B38: NIA | C38: Alumne/a | D38: Estat 3rT | E38: Esgota convocatòria | F38: Mòdul/s que esgota convocatòria | H38: Convocatòria extraordinària | I38: Mòduls - RA suspesos | J38: Decisió col·legiada | K38: Motivació - Observacions - Pla reforç -Extraordinària de gràcia
A39: 1 | B39: =IF('0 AVAL'!B36 = "", "", '0 AVAL'!B36) | C39: =IF('0 AVAL'!C36 = "", "", '0 AVAL'!C36) | E39: - | H39: - | J39: -
A40: 2 | B40: =IF('0 AVAL'!B37 = "", "", '0 AVAL'!B37) | C40: =IF('0 AVAL'!C37 = "", "", '0 AVAL'!C37) | E40: - | H40: - | J40: -
A41: 3 | B41: =IF('0 AVAL'!B38 = "", "", '0 AVAL'!B38) | C41: =IF('0 AVAL'!C38 = "", "", '0 AVAL'!C38) | E41: - | H41: - | J41: -
A42: 4 | B42: =IF('0 AVAL'!B39 = "", "", '0 AVAL'!B39) | C42: =IF('0 AVAL'!C39 = "", "", '0 AVAL'!C39) | E42: - | H42: - | J42: -
A43: 5 | B43: =IF('0 AVAL'!B40 = "", "", '0 AVAL'!B40) | C43: =IF('0 AVAL'!C40 = "", "", '0 AVAL'!C40) | E43: - | H43: - | J43: -
A44: 6 | B44: =IF('0 AVAL'!B41 = "", "", '0 AVAL'!B41) | C44: =IF('0 AVAL'!C41 = "", "", '0 AVAL'!C41) | E44: - | H44: - | J44: -
A45: 7 | B45: =IF('0 AVAL'!B42 = "", "", '0 AVAL'!B42) | C45: =IF('0 AVAL'!C42 = "", "", '0 AVAL'!C42) | E45: - | H45: - | J45: -
A46: 8 | B46: =IF('0 AVAL'!B43 = "", "", '0 AVAL'!B43) | C46: =IF('0 AVAL'!C43 = "", "", '0 AVAL'!C43) | E46: - | H46: - | J46: -
A47: 9 | B47: =IF('0 AVAL'!B44 = "", "", '0 AVAL'!B44) | C47: =IF('0 AVAL'!C44 = "", "", '0 AVAL'!C44) | E47: - | H47: - | J47: -
A48: 10 | B48: =IF('0 AVAL'!B45 = "", "", '0 AVAL'!B45) | C48: =IF('0 AVAL'!C45 = "", "", '0 AVAL'!C45) | E48: - | H48: - | J48: -
A49: 11 | B49: =IF('0 AVAL'!B46 = "", "", '0 AVAL'!B46) | C49: =IF('0 AVAL'!C46 = "", "", '0 AVAL'!C46) | E49: - | H49: - | J49: -
A50: 12 | B50: =IF('0 AVAL'!B47 = "", "", '0 AVAL'!B47) | C50: =IF('0 AVAL'!C47 = "", "", '0 AVAL'!C47) | E50: - | H50: - | J50: -
... A78: 40 | B78: =IF('0 AVAL'!B75 = "", "", '0 AVAL'!B75) | C78: =IF('0 AVAL'!C75 = "", "", '0 AVAL'!C75) | E78: - | H78: - | J78: -
...

Sheet EXTRAORD
I1: PC03.F01 Acta d'avaluació Ed.02 - Setem.25
B2: #VALUE! | D2: #VALUE!
I3: GRUP | J3: =IF(ficha_alum!K3 = "", "", ficha_alum!K3)
I4: TUTOR/A | J4: =IF(ficha_alum!K4 = "", "", ficha_alum!K4)
I5: CURS ESCOLAR | J5: =IF(ficha_alum!K5 = "", "", ficha_alum!K5)
I6: AVALUACIÓ | J6: Avaluació extraordinària
I7: DATA REUNIÓ
B9: 1- Estadístiques
B10: Inclou el valor (número) en les cel·les ombrejades en roig
D11: Núm. alu | L11: Núm. alu | M11: % sobre total | N11: Sobre avaluats
C12: Núm. alumnat total grup | D12: =COUNTIFS($C$24:$C$63,"<>",$D$24:$D$63,"<>Baixa")-COUNTBLANK($C$24:$C$63) -> 0 | E12: % sobre total extraordinària | G12: Núm. alumnat amb tot aprovat (final + extraordinària) | L12: =FINAL!L27+EXTRAORD!D17 -> 0 | M12: =IFERROR(L12/$D$12,"-") -> - | N12: =IFERROR(L12/($D$15+FINAL!$D$31),"-") -> -
C13: Núm. baixes confirmades | D13: =COUNTIFS($D$24:$D$63,"Baixa") -> 0 | E13: =IFERROR(D13/$D$12,"-") -> -
C14: Núm. alumnat extraordinària | D14: =COUNTIFS(FINAL!$C$39:$C$78,"<>",FINAL!$D$39:$D$78,"<>Baixa",FINAL!$H$39:$H$78,"Sí") -> 0 | E14: =IFERROR(D14/$D$12,"-") -> - | G14: Núm. alu. promociona (1r) - titula (2n) | L14: =FINAL!L33+COUNTIFS($C$24:$C$63,"<>",$D$24:$D$63,"<>Baixa",$G$24:$G$63,"Promociona / Titula") -> 0 | M14: =IFERROR(L14/$D$12,"-") -> - | N14: =IFERROR(L14/($D$15+FINAL!$D$31),"-") -> -
C15: Núm. alumnat avaluat | D15: 0 | E15: =IFERROR(D15/$D$14,"-") -> - | G15: Núm. alu. no promociona (1r) - no titula (2n) | L15: =D12-L14 -> 0 | M15: =IFERROR(L15/$D$12,"-") -> - | N15: =IFERROR(L15/($D$15+FINAL!$D$31),"-") -> -
C16: Núm. alumnat no avaluat | D16: 0 | E16: =IFERROR(D16/$D$14,"-") -> -
B17: Núm. alumnat amb tot aprovat en extraordinària | D17: 0 | E17: =IFERROR(D17/$D$14,"-") -> -
B21: 2- Anàlisi individual de l'alumnat
B23: NIA | C23: Alumne/a | D23: Estat 3rT | E23: Supera mòduls pendents | G23: Decisió col·legiada | I23: Observacions - Mòduls/RA no superats
A24: 1 | B24: =IF('0 AVAL'!B36 = "", "", '0 AVAL'!B36) | C24: =IF('0 AVAL'!C36 = "", "", '0 AVAL'!C36) | E24: - | G24: -
A25: 2 | B25: =IF('0 AVAL'!B37 = "", "", '0 AVAL'!B37) | C25: =IF('0 AVAL'!C37 = "", "", '0 AVAL'!C37) | E25: - | G25: -
A26: 3 | B26: =IF('0 AVAL'!B38 = "", "", '0 AVAL'!B38) | C26: =IF('0 AVAL'!C38 = "", "", '0 AVAL'!C38) | E26: - | G26: -
A27: 4 | B27: =IF('0 AVAL'!B39 = "", "", '0 AVAL'!B39) | C27: =IF('0 AVAL'!C39 = "", "", '0 AVAL'!C39) | E27: - | G27: -
A28: 5 | B28: =IF('0 AVAL'!B40 = "", "", '0 AVAL'!B40) | C28: =IF('0 AVAL'!C40 = "", "", '0 AVAL'!C40) | E28: - | G28: -
A29: 6 | B29: =IF('0 AVAL'!B41 = "", "", '0 AVAL'!B41) | C29: =IF('0 AVAL'!C41 = "", "", '0 AVAL'!C41) | E29: - | G29: -
A30: 7 | B30: =IF('0 AVAL'!B42 = "", "", '0 AVAL'!B42) | C30: =IF('0 AVAL'!C42 = "", "", '0 AVAL'!C42) | E30: - | G30: -
A31: 8 | B31: =IF('0 AVAL'!B43 = "", "", '0 AVAL'!B43) | C31: =IF('0 AVAL'!C43 = "", "", '0 AVAL'!C43) | E31: - | G31: -
A32: 9 | B32: =IF('0 AVAL'!B44 = "", "", '0 AVAL'!B44) | C32: =IF('0 AVAL'!C44 = "", "", '0 AVAL'!C44) | E32: - | G32: -
A33: 10 | B33: =IF('0 AVAL'!B45 = "", "", '0 AVAL'!B45) | C33: =IF('0 AVAL'!C45 = "", "", '0 AVAL'!C45) | E33: - | G33: -
A34: 11 | B34: =IF('0 AVAL'!B46 = "", "", '0 AVAL'!B46) | C34: =IF('0 AVAL'!C46 = "", "", '0 AVAL'!C46) | E34: - | G34: -
A35: 12 | B35: =IF('0 AVAL'!B47 = "", "", '0 AVAL'!B47) | C35: =IF('0 AVAL'!C47 = "", "", '0 AVAL'!C47) | E35: - | G35: -
... A63: 40 | B63: =IF('0 AVAL'!B75 = "", "", '0 AVAL'!B75) | C63: =IF('0 AVAL'!C75 = "", "", '0 AVAL'!C75) | E63: - | G63: -
B65: 3- Seguiments d'acords i mesures adoptades de manera consensuada per l'equip docent en anteriors reunions
J66: Seguiment | K66: Observacions
A67: 1
A68: 2
A69: 3
A70: 4
A71: 5
A72: 6
A73: 7
...

Sheet ED01
I1: Reunió equip docent | L1: Ed01 - Setem.25
B2: #VALUE! | D2: #VALUE!
I3: GRUP | J3: =IF(ficha_alum!K3 = "", "", ficha_alum!K3)
I4: TUTOR/A | J4: =IF(ficha_alum!K4 = "", "", ficha_alum!K4)
J5: =IF(ficha_alum!K5 = "", "", ficha_alum!K5)
I6: CURS ESCOLAR | J6: =IF(ficha_alum!K6 = "", "", ficha_alum!K6)
I7: DATA REUNIÓ
B9: 1- Seguiment i evolució del grup
B11: Revisió d'acords anteriors
B14: Anàlisis del rendiment general del grup - Punts forts (aspectes positius en l'aprenentatge, participació, ambient de grup, etc.)
B17: Anàlisi del rendiment general del grup - Aspectes a millorar (dificultats observades a nivell grupal ex. falta de participació, problemes de convivència, baixos resultats en determinats RA o mòduls)
B20: 2- Valoració del procés d'ensenyament-aprenentatge
B25: 3- Anàlisi individual de l'alumnat
B27: NIA | C27: Alumne/a | D27: Estat1rT | E27: Valoració del progrés en la consecució dels Resultats d'Aprenentatge (RA) i les competències professionals i per a l'ocupabilitat - Identificació d'alumnat amb progrés no adequat i registre del seguiment i suports individualitzats
A28: 1 | B28: =IF('0 AVAL'!B36 = "", "", '0 AVAL'!B36) | C28: =IF('0 AVAL'!C36 = "", "", '0 AVAL'!C36)
A29: 2 | B29: =IF('0 AVAL'!B37 = "", "", '0 AVAL'!B37) | C29: =IF('0 AVAL'!C37 = "", "", '0 AVAL'!C37)
A30: 3 | B30: =IF('0 AVAL'!B38 = "", "", '0 AVAL'!B38) | C30: =IF('0 AVAL'!C38 = "", "", '0 AVAL'!C38)
A31: 4 | B31: =IF('0 AVAL'!B39 = "", "", '0 AVAL'!B39) | C31: =IF('0 AVAL'!C39 = "", "", '0 AVAL'!C39)
A32: 5 | B32: =IF('0 AVAL'!B40 = "", "", '0 AVAL'!B40) | C32: =IF('0 AVAL'!C40 = "", "", '0 AVAL'!C40)
A33: 6 | B33: =IF('0 AVAL'!B41 = "", "", '0 AVAL'!B41) | C33: =IF('0 AVAL'!C41 = "", "", '0 AVAL'!C41)
A34: 7 | B34: =IF('0 AVAL'!B42 = "", "", '0 AVAL'!B42) | C34: =IF('0 AVAL'!C42 = "", "", '0 AVAL'!C42)
A35: 8 | B35: =IF('0 AVAL'!B43 = "", "", '0 AVAL'!B43) | C35: =IF('0 AVAL'!C43 = "", "", '0 AVAL'!C43)
A36: 9 | B36: =IF('0 AVAL'!B44 = "", "", '0 AVAL'!B44) | C36: =IF('0 AVAL'!C44 = "", "", '0 AVAL'!C44)
A37: 10 | B37: =IF('0 AVAL'!B45 = "", "", '0 AVAL'!B45) | C37: =IF('0 AVAL'!C45 = "", "", '0 AVAL'!C45)
A38: 11 | B38: =IF('0 AVAL'!B46 = "", "", '0 AVAL'!B46) | C38: =IF('0 AVAL'!C46 = "", "", '0 AVAL'!C46)
A39: 12 | B39: =IF('0 AVAL'!B47 = "", "", '0 AVAL'!B47) | C39: =IF('0 AVAL'!C47 = "", "", '0 AVAL'!C47)
... A67: 40 | B67: =IF('0 AVAL'!B75 = "", "", '0 AVAL'!B75) | C67: =IF('0 AVAL'!C75 = "", "", '0 AVAL'!C75)
B69: 4- Acords adoptats de caràcter col·legiat per l'equip docent. A partir dels resultats de les avaluacions del procés d'aprenentatge, es redefiniran propostes de millora del procés d'ensenyament.
A71: 1 | J71: Acta elaborada per: XXXXX. XX:XXh
A72: 2
A73: 3
A74: 4
A75: 5
A76: 6
A77: 7
B78: En aquest document s'està realitzant un tractament de dades de l'alumnat que està regulat per la normativa vigent en matèria de Protecció de Dades de Caràcter Personal (LOPD 3/2018 i Resolució Conselleria Educació, Investigació, Cultura i Esport del 28/6/2018). Recorda que les dades han de ser tractats de manera responsable i que has de guardar secret professional i no cedir o divulgar les dades ací contingudes.

Sheet ED02
I1: Reunió equip docent | L1: Ed01 - Setem.25
B2: #VALUE! | D2: #VALUE!
I3: GRUP | J3: =IF(ficha_alum!K3 = "", "", ficha_alum!K3)
I4: TUTOR/A | J4: =IF(ficha_alum!K4 = "", "", ficha_alum!K4)
J5: =IF(ficha_alum!K5 = "", "", ficha_alum!K5)
I6: CURS ESCOLAR | J6: =IF(ficha_alum!K6 = "", "", ficha_alum!K6)
I7: DATA REUNIÓ
B9: 1- Seguiment i evolució del grup
B11: Revisió d'acords anteriors
B14: Anàlisis del rendiment general del grup - Punts forts (aspectes positius en l'aprenentatge, participació, ambient de grup, etc.)
B17: Anàlisi del rendiment general del grup - Aspectes a millorar (dificultats observades a nivell grupal ex. falta de participació, problemes de convivència, baixos resultats en determinats RA o mòduls)
B20: 2- Valoració del procés d'ensenyament-aprenentatge
B25: 3- Anàlisi individual de l'alumnat
B27: NIA | C27: Alumne/a | D27: Estat2nT | E27: Valoració del progrés en la consecució dels Resultats d'Aprenentatge (RA) i les competències professionals i per a l'ocupabilitat - Identificació d'alumnat amb progrés no adequat i registre del seguiment i suports individualitzats
A28: 1 | B28: =IF('0 AVAL'!B36 = "", "", '0 AVAL'!B36) | C28: =IF('0 AVAL'!C36 = "", "", '0 AVAL'!C36)
A29: 2 | B29: =IF('0 AVAL'!B37 = "", "", '0 AVAL'!B37) | C29: =IF('0 AVAL'!C37 = "", "", '0 AVAL'!C37)
A30: 3 | B30: =IF('0 AVAL'!B38 = "", "", '0 AVAL'!B38) | C30: =IF('0 AVAL'!C38 = "", "", '0 AVAL'!C38)
A31: 4 | B31: =IF('0 AVAL'!B39 = "", "", '0 AVAL'!B39) | C31: =IF('0 AVAL'!C39 = "", "", '0 AVAL'!C39)
A32: 5 | B32: =IF('0 AVAL'!B40 = "", "", '0 AVAL'!B40) | C32: =IF('0 AVAL'!C40 = "", "", '0 AVAL'!C40)
A33: 6 | B33: =IF('0 AVAL'!B41 = "", "", '0 AVAL'!B41) | C33: =IF('0 AVAL'!C41 = "", "", '0 AVAL'!C41)
A34: 7 | B34: =IF('0 AVAL'!B42 = "", "", '0 AVAL'!B42) | C34: =IF('0 AVAL'!C42 = "", "", '0 AVAL'!C42)
A35: 8 | B35: =IF('0 AVAL'!B43 = "", "", '0 AVAL'!B43) | C35: =IF('0 AVAL'!C43 = "", "", '0 AVAL'!C43)
A36: 9 | B36: =IF('0 AVAL'!B44 = "", "", '0 AVAL'!B44) | C36: =IF('0 AVAL'!C44 = "", "", '0 AVAL'!C44)
A37: 10 | B37: =IF('0 AVAL'!B45 = "", "", '0 AVAL'!B45) | C37: =IF('0 AVAL'!C45 = "", "", '0 AVAL'!C45)
A38: 11 | B38: =IF('0 AVAL'!B46 = "", "", '0 AVAL'!B46) | C38: =IF('0 AVAL'!C46 = "", "", '0 AVAL'!C46)
A39: 12 | B39: =IF('0 AVAL'!B47 = "", "", '0 AVAL'!B47) | C39: =IF('0 AVAL'!C47 = "", "", '0 AVAL'!C47)
... A67: 40 | B67: =IF('0 AVAL'!B75 = "", "", '0 AVAL'!B75) | C67: =IF('0 AVAL'!C75 = "", "", '0 AVAL'!C75)
B69: 4- Acords adoptats de caràcter col·legiat per l'equip docent. A partir dels resultats de les avaluacions del procés d'aprenentatge, es redefiniran propostes de millora del procés d'ensenyament.
A71: 1 | J71: Acta elaborada per: XXXXX. XX:XXh
A72: 2
A73: 3
A74: 4
A75: 5
A76: 6
A77: 7
B78: En aquest document s'està realitzant un tractament de dades de l'alumnat que està regulat per la normativa vigent en matèria de Protecció de Dades de Caràcter Personal (LOPD 3/2018 i Resolució Conselleria Educació, Investigació, Cultura i Esport del 28/6/2018). Recorda que les dades han de ser tractats de manera responsable i que has de guardar secret professional i no cedir o divulgar les dades ací contingudes.

Sheet ED03
I1: Reunió equip docent | L1: Ed01 - Setem.25
B2: #VALUE! | D2: #VALUE!
I3: GRUP | J3: =IF(ficha_alum!K3 = "", "", ficha_alum!K3)
I4: TUTOR/A | J4: =IF(ficha_alum!K4 = "", "", ficha_alum!K4)
J5: =IF(ficha_alum!K5 = "", "", ficha_alum!K5)
I6: CURS ESCOLAR | J6: =IF(ficha_alum!K6 = "", "", ficha_alum!K6)
I7: DATA REUNIÓ
B9: 1- Seguiment i evolució del grup
B11: Revisió d'acords anteriors
B14: Anàlisis del rendiment general del grup - Punts forts (aspectes positius en l'aprenentatge, participació, ambient de grup, etc.)
B17: Anàlisi del rendiment general del grup - Aspectes a millorar (dificultats observades a nivell grupal ex. falta de participació, problemes de convivència, baixos resultats en determinats RA o mòduls)
B20: 2- Valoració del procés d'ensenyament-aprenentatge
B25: 3- Anàlisi individual de l'alumnat
B27: NIA | C27: Alumne/a | D27: Estat3rT | E27: Valoració del progrés en la consecució dels Resultats d'Aprenentatge (RA) i les competències professionals i per a l'ocupabilitat - Identificació d'alumnat amb progrés no adequat i registre del seguiment i suports individualitzats
A28: 1 | B28: =IF('0 AVAL'!B36 = "", "", '0 AVAL'!B36) | C28: =IF('0 AVAL'!C36 = "", "", '0 AVAL'!C36)
A29: 2 | B29: =IF('0 AVAL'!B37 = "", "", '0 AVAL'!B37) | C29: =IF('0 AVAL'!C37 = "", "", '0 AVAL'!C37)
A30: 3 | B30: =IF('0 AVAL'!B38 = "", "", '0 AVAL'!B38) | C30: =IF('0 AVAL'!C38 = "", "", '0 AVAL'!C38)
A31: 4 | B31: =IF('0 AVAL'!B39 = "", "", '0 AVAL'!B39) | C31: =IF('0 AVAL'!C39 = "", "", '0 AVAL'!C39)
A32: 5 | B32: =IF('0 AVAL'!B40 = "", "", '0 AVAL'!B40) | C32: =IF('0 AVAL'!C40 = "", "", '0 AVAL'!C40)
A33: 6 | B33: =IF('0 AVAL'!B41 = "", "", '0 AVAL'!B41) | C33: =IF('0 AVAL'!C41 = "", "", '0 AVAL'!C41)
A34: 7 | B34: =IF('0 AVAL'!B42 = "", "", '0 AVAL'!B42) | C34: =IF('0 AVAL'!C42 = "", "", '0 AVAL'!C42)
A35: 8 | B35: =IF('0 AVAL'!B43 = "", "", '0 AVAL'!B43) | C35: =IF('0 AVAL'!C43 = "", "", '0 AVAL'!C43)
A36: 9 | B36: =IF('0 AVAL'!B44 = "", "", '0 AVAL'!B44) | C36: =IF('0 AVAL'!C44 = "", "", '0 AVAL'!C44)
A37: 10 | B37: =IF('0 AVAL'!B45 = "", "", '0 AVAL'!B45) | C37: =IF('0 AVAL'!C45 = "", "", '0 AVAL'!C45)
A38: 11 | B38: =IF('0 AVAL'!B46 = "", "", '0 AVAL'!B46) | C38: =IF('0 AVAL'!C46 = "", "", '0 AVAL'!C46)
A39: 12 | B39: =IF('0 AVAL'!B47 = "", "", '0 AVAL'!B47) | C39: =IF('0 AVAL'!C47 = "", "", '0 AVAL'!C47)
... A67: 40 | B67: =IF('0 AVAL'!B75 = "", "", '0 AVAL'!B75) | C67: =IF('0 AVAL'!C75 = "", "", '0 AVAL'!C75)
B69: 4- Acords adoptats de caràcter col·legiat per l'equip docent. A partir dels resultats de les avaluacions del procés d'aprenentatge, es redefiniran propostes de millora del procés d'ensenyament.
A71: 1 | J71: Acta elaborada per: XXXXX. XX:XXh
A72: 2
A73: 3
A74: 4
A75: 5
A76: 6
A77: 7
B78: En aquest document s'està realitzant un tractament de dades de l'alumnat que està regulat per la normativa vigent en matèria de Protecció de Dades de Caràcter Personal (LOPD 3/2018 i Resolució Conselleria Educació, Investigació, Cultura i Esport del 28/6/2018). Recorda que les dades han de ser tractats de manera responsable i que has de guardar secret professional i no cedir o divulgar les dades ací contingudes.

Sheet ficha_alum
J1: Ficha Alumno | M1: Ed.02 - Setem.25
J3: GRUP
J4: TUTOR/A
J5: CURS ESCOLAR
A8: # | B8: NIA | C8: Nombre | D8: Apellido 1 | E8: Apellido 2 | F8: Nuss | G8: Fecha Nac. | H8: Sexo | I8: Documento | J8: Domicilio | K8: Número | L8: Puerta | M8: Cód. Postal | N8: Teléfono 1 | O8: Teléfono 2 | P8: Email 1 | Q8: Email 2 | R8: Enseñanza | S8: Curso | T8: Grupo | U8: Turno | V8: Repite
A9: 1
A10: 2
A11: 3
A12: 4
A13: 5
A14: 6
A15: 7
A16: 8
A17: 9
A18: 10
A19: 11
A20: 12
... A33: 25
